<mujoco model="scara">
  <compiler angle="radian" meshdir="assets" texturedir="assets" autolimits="true"/>

  <!-- <option cone="elliptic" impratio="100"/> --> <!-- Brax doesn't support cone_elliptic-->

  <default>
    <default class="scara">
      <geom friction="0.2" margin="0.001"/>
      <!-- <joint damping="1.0" frictionloss="0.03" armature="0.01"/> -->
      <joint damping="1.0" armature="0.01"/> <!-- Brax doesn't support frictionloss-->
      <position kp="60" ctrlrange="-3.141592 3.141592" forcerange="-7 7"/>

      <!-- Joints -->
      <default class="hombro">
        <joint range="0 3.14" axis="0 0 1"/>
        <position ctrlrange="0 3.14"/>
      </default>
      <default class="codo">
        <joint range="-2.96 2.96" axis="0 0 1"/>
        <position ctrlrange="-2.96 2.96"/>
      </default>
      <default class="z">
        <joint range="0 0.2" axis="0 0 -1" type="slide"/>
        <position ctrlrange="0 0.2"/>
      </default>
      <!-- visual -->
      <default class="visual">
        <geom type="mesh" contype="0" conaffinity="0" group="2" material="default_material"/>
      </default>
    </default>
  </default>

  <!-- Define assets -->
  <asset>
    <material name="default_material" specular="0" shininess="0.25" rgba="0.6 0.6 0.6 1"/>
    <material name="black" specular="0" shininess="0.25" rgba="0.15 0.15 0.15 1"/>
    <material name="collision_material" specular="0" shininess="0.25" rgba="1.0 0.5 0.0 0.8"/>
    <mesh class="scara" file="base_scara.obj"/>
    <mesh class="scara" file="hombro.obj"/>
    <mesh class="scara" file="codo.obj"/>
    <mesh class="scara" file="z.obj"/>
  </asset>

  <worldbody>
    <light name="spotlight" mode="targetbodycom" target="base_scara" pos="0 -1 2"/>

    <!-- Body -->
    <body name="base_scara" pos="0 0 0.285" childclass="scara">
      <inertial mass="1.410" pos="0.094622 0.000221 0.120537" quat="1 0 0 0" diaginertia="0.001 0.0007 0.0007"/>
      <geom class="visual" mesh="base_scara" material="default_material"/>

      <body name="link_hombro" pos="0 0 0.043">
        <joint class="hombro" name="hombro_joint"/>
        <inertial mass="0.248" pos="0 0 -0.02" quat="1 0 0 0" diaginertia="1E-4 1E-4 0.5E-4"/>
        <geom class="visual" mesh="hombro" quat="1 0 0 0" pos="0 0 0"/>

        <body name="link_codo" pos="0.3 0.0 0">
          <joint class="codo" name="codo_joint"/>
          <inertial mass="0.042" pos="0 0 -0.0625" quat="1 0 0 0" diaginertia="2E-5 2E-5 0.2E-5"/>
          <geom class="visual" mesh="codo" material="black" quat="1 0 0 0" pos="0 0 0"/>

          <body name="link_z" pos="0.33 0 -0.1">
            <joint class="z" name="z_joint"/>
            <inertial mass="0.1" pos="0 0 -0.06" quat="1 0 0 0" diaginertia="0.5E-3 0.5E-3 0.1E-3"/>
            <geom class="visual" mesh="z" quat="1 0 0 0" pos="0 0 0"/>
          </body>
        </body>
      </body>
    </body>
  </worldbody>

  <!-- Define actuators -->
  <!-- class: is the class of the joint
         name: is the label
         joint: the name of the joint where the actuator is set
    -->
  <actuator>


    <position class="hombro" name="hombro" joint="hombro_joint"/>
    <position class="codo" name="codo" joint="codo_joint"/>
    <position class="z" name="z" joint="z_joint"/>
  </actuator>
    <visual>
    <global offheight="600" offwidth="800"/>
    </visual>
  <!-- Commands that define the home posture -->
  <keyframe>
    <!-- x y z qw qx qy qz {qi} -->
    <!-- qi are the generalized coordinates of all the joints -->
    <key name="home" qpos="0 0 0"
      ctrl=" 0 0 0"/>
  </keyframe>
</mujoco>
  